inputs/input2.txt
2024-11-18-11-20-00 32 Ali MSFT Buy 30 40.0
2024-11-18-11-25-00 47 Emre MSFT Sell 10 42.0
2024-11-18-11-30-00 44 Oğuz MSFT Buy 16 20.0
2024-11-18-11-35-00 34 Mustafa MSFT Sell 18 28.0
2024-11-18-11-40-00 32 Ali MSFT Buy 24 35.0
2024-11-18-11-45-00 47 Emre MSFT Sell 20 19.0
2024-11-18-11-50-00 44 Oğuz MSFT Buy 19 45.0
2024-11-18-11-55-00 34 Mustafa MSFT Sell 38 24.0
