outputs/output2.txt
Ali bought 18 MSFT for 28.0 USD from Mustafa on 2024-11-18 at 11:35:00
Ali bought 12 MSFT for 19.0 USD from Emre on 2024-11-18 at 11:45:00
Oğuz bought 8 MSFT for 19.0 USD from Emre on 2024-11-18 at 11:45:00
Oğuz bought 10 MSFT for 42.0 USD from Emre on 2024-11-18 at 11:50:00
Ali bought 24 MSFT for 24.0 USD from Mustafa on 2024-11-18 at 11:55:00
Oğuz bought 9 MSFT for 24.0 USD from Mustafa on 2024-11-18 at 11:55:00
