inputs/input3.txt
2024-11-18-10-50-00 32 Ali AAPL Buy 1 44.0
2024-11-18-10-52-00 44 Oğuz AAPL Sell 1 42.0
2024-11-18-10-53-00 32 Ali AAPL Buy 1 45.0
2024-11-18-10-53-00 44 Oğuz AAPL Buy 1 43.0
2024-11-18-10-54-00 47 Emre AAPL Sell 1 40.0
2024-11-18-10-54-00 34 Mustafa AAPL Sell 1 39.0
