outputs/output3.txt
Ali bought 1 AAPL for 42.0 USD from Oğuz on 2024-11-18 at 10:52:00
Ali bought 1 AAPL for 39.0 USD from Mustafa on 2024-11-18 at 10:54:00
Oğuz bought 1 AAPL for 40.0 USD from Emre on 2024-11-18 at 10:54:00
