inputs/input4.txt
2024-11-18-10-10-15 34 Mustafa NVDA Buy 7 32.3
2024-11-18-10-10-30 44 Oğuz MRT Sell 15 31.6
2024-11-18-10-10-45 44 Oğuz AAPL Buy 8 34.3
2024-11-18-10-11-15 34 Mustafa NVDA Buy 7 39.2
2024-11-18-10-11-30 32 Ali BAC Sell 10 37.5
2024-11-18-10-11-45 34 Mustafa BAC Sell 5 42.0
2024-11-18-10-12-15 34 Mustafa BAC Buy 10 38.3
2024-11-18-10-12-30 34 Mustafa AAPL Sell 18 33.6
2024-11-18-10-12-45 47 Emre MRT Buy 8 33.1
2024-11-18-10-13-15 32 Ali MRT Buy 12 40.8
2024-11-18-10-13-30 47 Emre BAC Sell 18 31.1
2024-11-18-10-13-45 34 Mustafa AAPL Sell 11 38.7
2024-11-18-10-14-15 32 Ali NVDA Sell 17 39.5
2024-11-18-10-14-30 32 Ali MRT Buy 16 36.5
2024-11-18-10-14-45 34 Mustafa MRT Sell 13 39.4
2024-11-18-10-15-15 34 Mustafa NVDA Sell 10 35.7
2024-11-18-10-15-30 44 Oğuz AAPL Sell 7 39.6
2024-11-18-10-15-45 32 Ali BAC Sell 11 36.8
2024-11-18-10-16-15 44 Oğuz AAPL Buy 20 33.4
2024-11-18-10-16-30 44 Oğuz AAPL Sell 18 37.9
2024-11-18-10-16-45 44 Oğuz MRT Buy 19 43.1
2024-11-18-10-17-15 47 Emre NVDA Sell 17 32.9
2024-11-18-10-17-30 47 Emre BAC Sell 19 41.7
2024-11-18-10-17-45 47 Emre MSFT Buy 16 36.8
2024-11-18-10-18-15 34 Mustafa BAC Sell 19 32.9
2024-11-18-10-18-30 32 Ali MRT Buy 14 42.9
2024-11-18-10-18-45 47 Emre BAC Sell 6 41.4
2024-11-18-10-19-15 32 Ali MRT Buy 5 38.4
2024-11-18-10-19-30 32 Ali MSFT Buy 9 35.8
2024-11-18-10-19-45 44 Oğuz MRT Sell 7 30.7
2024-11-18-10-20-15 47 Emre BAC Sell 7 32.7
2024-11-18-10-20-30 32 Ali MSFT Sell 5 40.9
2024-11-18-10-20-45 32 Ali BAC Sell 17 44.7
2024-11-18-10-21-15 32 Ali AAPL Buy 11 41.3
2024-11-18-10-21-30 47 Emre MRT Sell 16 39.3
2024-11-18-10-21-45 32 Ali MRT Sell 16 36.3
2024-11-18-10-22-15 32 Ali AAPL Sell 7 35.4
2024-11-18-10-22-30 32 Ali MRT Buy 7 39.3
2024-11-18-10-22-45 47 Emre NVDA Buy 12 41.3
2024-11-18-10-23-15 47 Emre MSFT Buy 11 42.4
2024-11-18-10-23-30 32 Ali AAPL Sell 9 32.4
2024-11-18-10-23-45 47 Emre AAPL Buy 19 34.7
2024-11-18-10-24-15 34 Mustafa MRT Sell 16 33.8
2024-11-18-10-24-30 44 Oğuz BAC Sell 16 44.0
2024-11-18-10-24-45 34 Mustafa BAC Buy 13 30.6
2024-11-18-10-25-15 44 Oğuz MRT Buy 12 32.0
2024-11-18-10-25-30 44 Oğuz MRT Sell 19 38.4
2024-11-18-10-25-45 32 Ali MSFT Sell 5 34.3
2024-11-18-10-26-15 32 Ali NVDA Sell 9 41.0
2024-11-18-10-26-30 32 Ali AAPL Sell 12 39.7
2024-11-18-10-26-45 44 Oğuz MRT Sell 7 35.8
2024-11-18-10-27-15 34 Mustafa MRT Sell 11 36.2
2024-11-18-10-27-30 32 Ali MSFT Buy 14 30.3
2024-11-18-10-27-45 44 Oğuz NVDA Sell 7 42.7
2024-11-18-10-28-15 34 Mustafa BAC Buy 8 37.3
2024-11-18-10-28-30 47 Emre BAC Buy 14 34.8
2024-11-18-10-28-45 47 Emre AAPL Buy 15 36.5
2024-11-18-10-29-15 32 Ali AAPL Buy 8 34.6
2024-11-18-10-29-30 44 Oğuz BAC Sell 8 34.5
2024-11-18-10-29-45 44 Oğuz BAC Sell 12 40.7
2024-11-18-10-30-15 44 Oğuz NVDA Sell 14 37.1
2024-11-18-10-30-30 34 Mustafa AAPL Sell 14 43.6
2024-11-18-10-30-45 44 Oğuz NVDA Sell 10 33.0
2024-11-18-10-31-15 34 Mustafa AAPL Sell 19 43.3
2024-11-18-10-31-30 47 Emre NVDA Sell 17 44.2
2024-11-18-10-31-45 44 Oğuz NVDA Sell 12 40.0
2024-11-18-10-32-15 44 Oğuz BAC Buy 15 32.4
2024-11-18-10-32-30 47 Emre NVDA Buy 13 35.0
2024-11-18-10-32-45 47 Emre MRT Buy 9 32.2
2024-11-18-10-33-15 47 Emre BAC Buy 7 33.1
2024-11-18-10-33-30 44 Oğuz NVDA Sell 7 43.3
2024-11-18-10-33-45 47 Emre MRT Buy 20 43.9
2024-11-18-10-34-15 32 Ali NVDA Buy 7 32.6
2024-11-18-10-34-30 44 Oğuz MRT Buy 9 35.7
2024-11-18-10-34-45 34 Mustafa BAC Sell 14 40.1
2024-11-18-10-35-15 34 Mustafa NVDA Sell 9 32.7
2024-11-18-10-35-30 34 Mustafa MRT Buy 9 34.8
2024-11-18-10-35-45 32 Ali AAPL Buy 18 33.9
2024-11-18-10-36-15 34 Mustafa BAC Buy 9 32.0
2024-11-18-10-36-30 44 Oğuz MSFT Sell 18 36.8
2024-11-18-10-36-45 32 Ali MSFT Sell 7 43.9
2024-11-18-10-37-15 44 Oğuz NVDA Buy 5 43.2
2024-11-18-10-37-30 34 Mustafa AAPL Buy 16 39.8
2024-11-18-10-37-45 34 Mustafa MSFT Buy 8 32.4
2024-11-18-10-38-15 44 Oğuz NVDA Buy 9 40.6
2024-11-18-10-38-30 44 Oğuz NVDA Sell 20 39.3
2024-11-18-10-38-45 34 Mustafa MSFT Buy 15 41.7
2024-11-18-10-39-15 47 Emre BAC Sell 8 38.9
2024-11-18-10-39-30 34 Mustafa MSFT Buy 7 41.6
2024-11-18-10-39-45 47 Emre AAPL Sell 11 41.9
2024-11-18-10-40-15 44 Oğuz BAC Sell 8 42.7
2024-11-18-10-40-30 47 Emre BAC Buy 7 35.7
2024-11-18-10-40-45 47 Emre NVDA Buy 18 32.9
2024-11-18-10-41-15 44 Oğuz MSFT Sell 8 30.0
2024-11-18-10-41-30 44 Oğuz NVDA Buy 9 32.5
2024-11-18-10-41-45 34 Mustafa AAPL Buy 5 44.1
2024-11-18-10-42-15 32 Ali BAC Buy 7 32.1
2024-11-18-10-42-30 34 Mustafa MSFT Sell 7 31.9
2024-11-18-10-42-45 32 Ali AAPL Buy 7 39.7
2024-11-18-10-43-15 34 Mustafa AAPL Buy 15 36.0
2024-11-18-10-43-30 32 Ali MRT Sell 20 36.2
2024-11-18-10-43-45 34 Mustafa MRT Buy 6 31.2
2024-11-18-10-44-15 32 Ali MRT Sell 8 42.3
2024-11-18-10-44-30 32 Ali NVDA Buy 15 38.5
2024-11-18-10-44-45 32 Ali NVDA Sell 6 43.1
2024-11-18-10-45-15 34 Mustafa NVDA Sell 19 44.1
2024-11-18-10-45-30 44 Oğuz BAC Buy 5 41.2
2024-11-18-10-45-45 47 Emre NVDA Buy 11 38.5
2024-11-18-10-46-15 34 Mustafa MSFT Buy 10 30.9
2024-11-18-10-46-30 32 Ali AAPL Sell 15 33.5
2024-11-18-10-46-45 47 Emre AAPL Sell 20 33.7
2024-11-18-10-47-15 44 Oğuz MSFT Sell 14 37.9
2024-11-18-10-47-30 32 Ali NVDA Buy 13 38.8
2024-11-18-10-47-45 34 Mustafa MSFT Buy 8 44.1
2024-11-18-10-48-15 47 Emre NVDA Buy 6 37.6
2024-11-18-10-48-30 47 Emre MSFT Sell 18 34.1
2024-11-18-10-48-45 44 Oğuz MSFT Buy 17 37.7
2024-11-18-10-49-15 34 Mustafa NVDA Buy 9 32.9
2024-11-18-10-49-30 34 Mustafa AAPL Buy 15 35.4
2024-11-18-10-49-45 44 Oğuz AAPL Buy 16 36.5
2024-11-18-10-50-15 47 Emre MSFT Sell 11 35.9
2024-11-18-10-50-30 32 Ali MRT Buy 16 41.2
2024-11-18-10-50-45 32 Ali AAPL Sell 8 43.5
2024-11-18-10-51-15 34 Mustafa NVDA Sell 12 36.6
2024-11-18-10-51-30 44 Oğuz MSFT Sell 8 36.0
2024-11-18-10-51-45 34 Mustafa MSFT Sell 14 31.0
2024-11-18-10-52-15 47 Emre NVDA Sell 20 37.3
2024-11-18-10-52-30 32 Ali AAPL Sell 12 33.6
2024-11-18-10-52-45 44 Oğuz MSFT Buy 14 39.0
2024-11-18-10-53-15 47 Emre BAC Sell 8 32.3
2024-11-18-10-53-30 44 Oğuz AAPL Sell 16 42.1
2024-11-18-10-53-45 34 Mustafa BAC Sell 19 39.7
2024-11-18-10-54-15 32 Ali MSFT Buy 13 35.0
2024-11-18-10-54-30 47 Emre MRT Sell 7 32.2
2024-11-18-10-54-45 34 Mustafa BAC Buy 18 34.6
2024-11-18-10-55-15 32 Ali MRT Buy 6 41.1
2024-11-18-10-55-30 44 Oğuz MRT Sell 14 44.3
2024-11-18-10-55-45 34 Mustafa BAC Sell 12 43.5
2024-11-18-10-56-15 32 Ali BAC Buy 5 31.5
2024-11-18-10-56-30 34 Mustafa MRT Sell 17 32.9
2024-11-18-10-56-45 47 Emre NVDA Buy 15 30.0
2024-11-18-10-57-15 47 Emre BAC Buy 13 32.2
2024-11-18-10-57-30 47 Emre NVDA Sell 16 34.0
2024-11-18-10-57-45 44 Oğuz AAPL Sell 14 36.0
2024-11-18-10-58-15 47 Emre AAPL Buy 12 44.7
2024-11-18-10-58-30 47 Emre BAC Sell 10 34.4
2024-11-18-10-58-45 44 Oğuz MSFT Buy 17 40.8
2024-11-18-11-10-15 32 Ali NVDA Sell 12 34.2
2024-11-18-11-10-30 34 Mustafa BAC Buy 19 38.5
2024-11-18-11-10-45 32 Ali MSFT Sell 19 37.3
2024-11-18-11-11-15 32 Ali BAC Buy 19 43.0
2024-11-18-11-11-30 32 Ali AAPL Buy 9 31.0
2024-11-18-11-11-45 47 Emre BAC Buy 15 44.3
2024-11-18-11-12-15 47 Emre MSFT Sell 9 32.1
2024-11-18-11-12-30 34 Mustafa MSFT Sell 13 39.8
2024-11-18-11-12-45 44 Oğuz BAC Sell 8 39.4
2024-11-18-11-13-15 44 Oğuz MSFT Buy 17 30.2
2024-11-18-11-13-30 44 Oğuz BAC Sell 13 35.4
2024-11-18-11-13-45 44 Oğuz AAPL Sell 8 40.8
2024-11-18-11-14-15 34 Mustafa BAC Buy 15 31.9
2024-11-18-11-14-30 44 Oğuz AAPL Buy 15 39.2
2024-11-18-11-14-45 34 Mustafa MSFT Sell 18 31.7
2024-11-18-11-15-15 44 Oğuz AAPL Buy 15 36.3
2024-11-18-11-15-30 44 Oğuz BAC Buy 16 34.4
2024-11-18-11-15-45 32 Ali MRT Sell 14 37.8
2024-11-18-11-16-15 34 Mustafa MSFT Buy 20 36.6
2024-11-18-11-16-30 44 Oğuz AAPL Sell 9 41.9
2024-11-18-11-16-45 47 Emre NVDA Buy 15 41.9
2024-11-18-11-17-15 44 Oğuz AAPL Buy 11 41.3
2024-11-18-11-17-30 47 Emre BAC Buy 16 42.1
2024-11-18-11-17-45 34 Mustafa NVDA Sell 14 44.8
2024-11-18-11-18-15 47 Emre MRT Buy 12 40.3
2024-11-18-11-18-30 32 Ali NVDA Buy 11 36.0
2024-11-18-11-18-45 44 Oğuz MSFT Sell 13 33.5
2024-11-18-11-19-15 32 Ali NVDA Sell 16 32.3
2024-11-18-11-19-30 44 Oğuz MSFT Sell 16 30.9
2024-11-18-11-19-45 44 Oğuz BAC Buy 16 44.1
