outputs/output4.txt
Mustafa bought 10 BAC for 37.5 USD from Ali on 2024-11-18 at 10:12:15
Oğuz bought 8 AAPL for 33.6 USD from Mustafa on 2024-11-18 at 10:12:30
Emre bought 8 MRT for 31.6 USD from Oğuz on 2024-11-18 at 10:12:45
Ali bought 7 MRT for 31.6 USD from Oğuz on 2024-11-18 at 10:13:15
Ali bought 5 MRT for 39.4 USD from Mustafa on 2024-11-18 at 10:14:45
Oğuz bought 8 MRT for 39.4 USD from Mustafa on 2024-11-18 at 10:16:45
Mustafa bought 7 NVDA for 32.9 USD from Emre on 2024-11-18 at 10:17:15
Ali bought 7 MRT for 30.7 USD from Oğuz on 2024-11-18 at 10:19:45
Ali bought 10 AAPL for 33.6 USD from Mustafa on 2024-11-18 at 10:21:15
Ali bought 1 AAPL for 38.7 USD from Mustafa on 2024-11-18 at 10:21:15
Oğuz bought 11 MRT for 39.3 USD from Emre on 2024-11-18 at 10:21:30
Ali bought 5 MRT for 39.3 USD from Emre on 2024-11-18 at 10:21:30
Emre bought 12 NVDA for 39.5 USD from Ali on 2024-11-18 at 10:22:45
Emre bought 5 MSFT for 40.9 USD from Ali on 2024-11-18 at 10:23:15
Oğuz bought 9 AAPL for 32.4 USD from Ali on 2024-11-18 at 10:23:30
Ali bought 9 MRT for 33.8 USD from Mustafa on 2024-11-18 at 10:24:15
Ali bought 7 MRT for 33.8 USD from Mustafa on 2024-11-18 at 10:24:15
Ali bought 2 MRT for 38.4 USD from Oğuz on 2024-11-18 at 10:25:30
Ali bought 5 MRT for 38.4 USD from Oğuz on 2024-11-18 at 10:25:30
Ali bought 7 MRT for 38.4 USD from Oğuz on 2024-11-18 at 10:25:30
Emre bought 5 MSFT for 34.3 USD from Ali on 2024-11-18 at 10:25:45
Mustafa bought 8 BAC for 31.1 USD from Emre on 2024-11-18 at 10:28:15
Emre bought 14 BAC for 32.9 USD from Mustafa on 2024-11-18 at 10:28:30
Emre bought 7 AAPL for 35.4 USD from Ali on 2024-11-18 at 10:28:45
Oğuz bought 10 BAC for 31.1 USD from Emre on 2024-11-18 at 10:32:15
Emre bought 10 NVDA for 33.0 USD from Oğuz on 2024-11-18 at 10:32:30
Emre bought 5 BAC for 32.9 USD from Mustafa on 2024-11-18 at 10:33:15
Emre bought 16 MRT for 36.3 USD from Ali on 2024-11-18 at 10:33:45
Emre bought 4 MRT for 38.4 USD from Oğuz on 2024-11-18 at 10:33:45
Emre bought 3 NVDA for 32.7 USD from Mustafa on 2024-11-18 at 10:35:15
Emre bought 11 MSFT for 36.8 USD from Oğuz on 2024-11-18 at 10:36:30
Emre bought 6 MSFT for 36.8 USD from Oğuz on 2024-11-18 at 10:36:30
Oğuz bought 5 NVDA for 39.5 USD from Ali on 2024-11-18 at 10:37:15
Mustafa bought 7 AAPL for 39.6 USD from Oğuz on 2024-11-18 at 10:37:30
Mustafa bought 9 AAPL for 37.9 USD from Oğuz on 2024-11-18 at 10:37:30
Oğuz bought 9 NVDA for 35.7 USD from Mustafa on 2024-11-18 at 10:38:15
Mustafa bought 1 MSFT for 36.8 USD from Oğuz on 2024-11-18 at 10:38:45
Emre bought 7 BAC for 34.5 USD from Oğuz on 2024-11-18 at 10:40:30
Emre bought 6 NVDA for 32.7 USD from Mustafa on 2024-11-18 at 10:40:45
Ali bought 8 MSFT for 30.0 USD from Oğuz on 2024-11-18 at 10:41:15
Mustafa bought 5 AAPL for 37.9 USD from Oğuz on 2024-11-18 at 10:41:45
Ali bought 1 MSFT for 31.9 USD from Mustafa on 2024-11-18 at 10:42:30
Ali bought 7 AAPL for 38.7 USD from Mustafa on 2024-11-18 at 10:42:45
Ali bought 1 NVDA for 35.7 USD from Mustafa on 2024-11-18 at 10:44:30
Ali bought 10 NVDA for 32.9 USD from Emre on 2024-11-18 at 10:44:30
Ali bought 4 NVDA for 37.1 USD from Oğuz on 2024-11-18 at 10:44:30
Oğuz bought 5 BAC for 36.8 USD from Ali on 2024-11-18 at 10:45:30
Emre bought 10 NVDA for 37.1 USD from Oğuz on 2024-11-18 at 10:45:45
Emre bought 15 AAPL for 33.5 USD from Ali on 2024-11-18 at 10:46:30
Ali bought 8 AAPL for 33.7 USD from Emre on 2024-11-18 at 10:46:45
Ali bought 12 AAPL for 33.7 USD from Emre on 2024-11-18 at 10:46:45
Mustafa bought 14 MSFT for 37.9 USD from Oğuz on 2024-11-18 at 10:47:15
Mustafa bought 7 MSFT for 43.9 USD from Ali on 2024-11-18 at 10:47:45
Mustafa bought 7 MSFT for 34.1 USD from Emre on 2024-11-18 at 10:48:30
Mustafa bought 1 MSFT for 34.1 USD from Emre on 2024-11-18 at 10:48:30
Oğuz bought 6 MSFT for 31.9 USD from Mustafa on 2024-11-18 at 10:48:45
Oğuz bought 10 MSFT for 34.1 USD from Emre on 2024-11-18 at 10:48:45
Oğuz bought 1 MSFT for 35.9 USD from Emre on 2024-11-18 at 10:50:15
Ali bought 1 MRT for 38.4 USD from Oğuz on 2024-11-18 at 10:50:30
Ali bought 7 MRT for 35.8 USD from Oğuz on 2024-11-18 at 10:50:30
Ali bought 8 MRT for 36.2 USD from Mustafa on 2024-11-18 at 10:50:30
Emre bought 1 NVDA for 36.6 USD from Mustafa on 2024-11-18 at 10:51:15
Ali bought 11 NVDA for 36.6 USD from Mustafa on 2024-11-18 at 10:51:15
Ali bought 2 NVDA for 37.3 USD from Emre on 2024-11-18 at 10:52:15
Emre bought 4 AAPL for 33.6 USD from Ali on 2024-11-18 at 10:52:30
Emre bought 8 AAPL for 33.6 USD from Ali on 2024-11-18 at 10:52:30
Oğuz bought 10 MSFT for 35.9 USD from Emre on 2024-11-18 at 10:52:45
Oğuz bought 4 MSFT for 31.0 USD from Mustafa on 2024-11-18 at 10:52:45
Oğuz bought 5 BAC for 32.3 USD from Emre on 2024-11-18 at 10:53:15
Ali bought 10 MSFT for 31.0 USD from Mustafa on 2024-11-18 at 10:54:15
Oğuz bought 7 MRT for 32.2 USD from Emre on 2024-11-18 at 10:54:30
Mustafa bought 7 BAC for 32.7 USD from Emre on 2024-11-18 at 10:54:45
Mustafa bought 1 BAC for 34.5 USD from Oğuz on 2024-11-18 at 10:54:45
Mustafa bought 3 BAC for 32.3 USD from Emre on 2024-11-18 at 10:54:45
Ali bought 3 MRT for 36.2 USD from Mustafa on 2024-11-18 at 10:55:15
Oğuz bought 2 MRT for 32.9 USD from Mustafa on 2024-11-18 at 10:56:30
Ali bought 3 MRT for 32.9 USD from Mustafa on 2024-11-18 at 10:56:30
Mustafa bought 14 AAPL for 36.0 USD from Oğuz on 2024-11-18 at 10:57:45
Emre bought 3 AAPL for 38.7 USD from Mustafa on 2024-11-18 at 10:58:15
Emre bought 4 AAPL for 37.9 USD from Oğuz on 2024-11-18 at 10:58:15
Emre bought 5 AAPL for 39.7 USD from Ali on 2024-11-18 at 10:58:15
Mustafa bought 7 BAC for 34.4 USD from Emre on 2024-11-18 at 10:58:30
Emre bought 6 NVDA for 34.2 USD from Ali on 2024-11-18 at 11:10:15
Mustafa bought 6 BAC for 36.8 USD from Ali on 2024-11-18 at 11:10:30
Mustafa bought 3 BAC for 34.4 USD from Emre on 2024-11-18 at 11:10:30
Oğuz bought 17 MSFT for 37.3 USD from Ali on 2024-11-18 at 11:10:45
Ali bought 5 BAC for 42.0 USD from Mustafa on 2024-11-18 at 11:11:15
Ali bought 14 BAC for 41.7 USD from Emre on 2024-11-18 at 11:11:15
Emre bought 15 BAC for 44.0 USD from Oğuz on 2024-11-18 at 11:11:45
Mustafa bought 8 MSFT for 32.1 USD from Emre on 2024-11-18 at 11:12:15
Ali bought 1 MSFT for 32.1 USD from Emre on 2024-11-18 at 11:12:15
Mustafa bought 10 BAC for 35.4 USD from Oğuz on 2024-11-18 at 11:13:30
Ali bought 2 MSFT for 31.7 USD from Mustafa on 2024-11-18 at 11:14:45
Mustafa bought 8 MSFT for 36.0 USD from Oğuz on 2024-11-18 at 11:16:15
Emre bought 9 NVDA for 41.0 USD from Ali on 2024-11-18 at 11:16:45
Emre bought 6 NVDA for 40.0 USD from Oğuz on 2024-11-18 at 11:16:45
Oğuz bought 7 AAPL for 39.7 USD from Ali on 2024-11-18 at 11:17:15
Emre bought 12 BAC for 40.7 USD from Oğuz on 2024-11-18 at 11:17:30
Emre bought 4 BAC for 40.1 USD from Mustafa on 2024-11-18 at 11:17:30
Emre bought 12 MRT for 36.2 USD from Ali on 2024-11-18 at 11:18:15
Ali bought 11 NVDA for 34.0 USD from Emre on 2024-11-18 at 11:18:30
Mustafa bought 12 MSFT for 33.5 USD from Oğuz on 2024-11-18 at 11:18:45
Mustafa bought 7 NVDA for 32.3 USD from Ali on 2024-11-18 at 11:19:15
Emre bought 9 NVDA for 32.3 USD from Ali on 2024-11-18 at 11:19:15
Mustafa bought 10 MSFT for 30.9 USD from Oğuz on 2024-11-18 at 11:19:30
Oğuz bought 5 BAC for 41.7 USD from Emre on 2024-11-18 at 11:19:45
Oğuz bought 6 BAC for 41.4 USD from Emre on 2024-11-18 at 11:19:45
Oğuz bought 5 BAC for 40.1 USD from Mustafa on 2024-11-18 at 11:19:45
Emre bought 2 MSFT for 37.3 USD from Ali on 2024-11-18 at 11:21:15
Emre bought 11 MSFT for 39.8 USD from Mustafa on 2024-11-18 at 11:21:15
Oğuz bought 8 MRT for 36.2 USD from Ali on 2024-11-18 at 11:22:15
Oğuz bought 3 MRT for 42.3 USD from Ali on 2024-11-18 at 11:22:15
Oğuz bought 11 AAPL for 33.4 USD from Emre on 2024-11-18 at 11:23:30
Ali bought 6 AAPL for 33.4 USD from Emre on 2024-11-18 at 11:23:30
Mustafa bought 1 AAPL for 33.4 USD from Emre on 2024-11-18 at 11:23:30
Mustafa bought 1 AAPL for 33.4 USD from Emre on 2024-11-18 at 11:23:30
Mustafa bought 1 BAC for 44.0 USD from Oğuz on 2024-11-18 at 11:24:15
